Workbook
Name actual_month: [4]Summary!$I$1
Name cash: #REF!
Name curs: #REF!
Name DANE: '[9]Breakdown CAPEX (PBC)'!$A$6:$J$365
Name eur_rate: [11]Summary!$D$109
Name k: #REF!
Name POW: [13]POW!$A$2:$D$6
Name rate: #REF!
Name tolerance: [14]Inputs!#REF!
Name usd_rur: '[15]Narratives-Subsidiarie'!$F$2
Name Город: #REF!
Name допкоды: #REF!
Name ДоходВсегоПлан: #REF!
Name ДоходВсегоФакт: #REF!
Name доходы1: #REF!
Name доходы2: #REF!
Name Индекс: #REF!
Name Инпутс: #REF!
Name коды: #REF!
Name курс: #REF!
Name МЛН: 1000000
Name Налог_на_прибыль: '[17]input data'!$E$73
Name Отчисления_от_зпл: 0.385
Name па: #REF!
Name ПланФакт: #REF!
Name Площадь: '[18]input data'!$F$19
Name Площадь_гараж: #REF!
Name Площадь_жилая: '[17]input data'!$F$19
Name Площадь_общая: #REF!
Name поступления1: #REF!
Name Поступления2: #REF!
Name ПрРасходыВсегоПлан: #REF!
Name ПрРасходыВсегоФакт: #REF!
Name РасходыВсегоПлан: #REF!
Name РасходыВсегоФакт: #REF!
Name расходыпр1: #REF!
Name расходыпр2: #REF!
Name расходытек1: #REF!
Name расходытек2: #REF!
Name руб.: "остаток вход"
Name ТекРасходыВсегоПлан: #REF!
Name ТекРасходыВсегоФакт: #REF!

Sheet Сводные
G1: Отчет о выполненных работах к приложению №13 к Договору от 17.06.2025 № ДОМУ/2025-06/17 от ИП СИЗОВА ВП
A2: 1 очередь | B2: С1 | C2: С2 | D2: С3-1 | E2: С3-2 | H2: Индексация цен
A3: корпуса С1 С3 | H3: до ввода 1 оч | I3: после ввода 1 оч
A4: Кол-во спален | B4: Сред. площадь, кв. м | C4: Кол-во, шт. | D4: % | E4: Средневзв стартовая цена, руб. | H4: 0.01 | I4: 0.01
A5: Ст | B5: {=AVERAGE( IF((PriceList[Количество комнат]=A5)* ((PriceList[Корпус]=$B$2)+(PriceList[Корпус]=$D$2)+(PriceList[Корпус]=$E$2)), PriceList[Площадь, кв.м] ) )} -> 32.306155 | C5: {=SUM( IF((PriceList[Количество комнат]=A5)* ((PriceList[Корпус]=$B$2)+(PriceList[Корпус]=$D$2)+(PriceList[Корпус]=$E$2)), 1) )} -> 593 | D5: =C5/$C$8 -> 0.88375559 | E5: {=SUMPRODUCT((PriceList[Комнат в шахматку]=A5)*((PriceList[Корпус]=$B$2)+(PriceList[Корпус]=$D$2)+(PriceList[Корпус]=$E$2))*PriceList[ИТОГ Бюджет, руб]) / SUMPRODUCT((PriceList[Комнат в шахматку]=A5)*((PriceList[Корпус]=$B$2)+(PriceList[Корпус]=$D$2)+(PriceList[Корпус]=$E$2))*PriceList[Площадь, кв.м])} -> 365482.87 | K5: Доля
A6: 1К | B6: {=AVERAGE( IF((PriceList[Количество комнат]=A6)* ((PriceList[Корпус]=$B$2)+(PriceList[Корпус]=$D$2)+(PriceList[Корпус]=$E$2)), PriceList[Площадь, кв.м] ) )} -> 57.891818 | C6: {=SUM( IF((PriceList[Количество комнат]=A6)* ((PriceList[Корпус]=$B$2)+(PriceList[Корпус]=$D$2)+(PriceList[Корпус]=$E$2)), 1) )} -> 77 | D6: =C6/$C$8 -> 0.1147541 | E6: {=SUMPRODUCT((PriceList[Комнат в шахматку]=A6)*((PriceList[Корпус]=$B$2)+(PriceList[Корпус]=$D$2)+(PriceList[Корпус]=$E$2))*PriceList[ИТОГ Бюджет, руб]) / SUMPRODUCT((PriceList[Комнат в шахматку]=A6)*((PriceList[Корпус]=$B$2)+(PriceList[Корпус]=$D$2)+(PriceList[Корпус]=$E$2))*PriceList[Площадь, кв.м])} -> 358555.66 | H6: Кладовые | I6: =1050-76 -> 974 | J6: =#REF! -> #REF! | K6: =I6/J6 -> #REF!
A7: 2К | B7: {=AVERAGE( IF((PriceList[Количество комнат]=A7)* ((PriceList[Корпус]=$B$2)+(PriceList[Корпус]=$D$2)+(PriceList[Корпус]=$E$2)), PriceList[Площадь, кв.м] ) )} -> 82.76 | C7: {=SUM( IF((PriceList[Количество комнат]=A7)* ((PriceList[Корпус]=$B$2)+(PriceList[Корпус]=$D$2)+(PriceList[Корпус]=$E$2)), 1) )} -> 1 | D7: =C7/$C$8 -> 0.001490313 | E7: {=SUMPRODUCT((PriceList[Комнат в шахматку]=A7)*((PriceList[Корпус]=$B$2)+(PriceList[Корпус]=$D$2)+(PriceList[Корпус]=$E$2))*PriceList[ИТОГ Бюджет, руб]) / SUMPRODUCT((PriceList[Комнат в шахматку]=A7)*((PriceList[Корпус]=$B$2)+(PriceList[Корпус]=$D$2)+(PriceList[Корпус]=$E$2))*PriceList[Площадь, кв.м])} -> 413118.72 | H7: Машиноместа | I7: 477 | K7: =I7/J6 -> #REF!
C8: =SUM(C5:C7) -> 671 | D8: =SUM(D5:D7) -> 1 | E8: =(SUMIF(PriceList[Корпус],Сводные!B2,PriceList[ИТОГ Бюджет, руб]) +SUMIF(PriceList[Корпус],Сводные!D2,PriceList[ИТОГ Бюджет, руб]) +SUMIF(PriceList[Корпус],Сводные!E2,PriceList[ИТОГ Бюджет, руб])) / (SUMIF(PriceList[Корпус],Сводные!B2,PriceList[Площадь, кв.м]) +SUMIF(PriceList[Корпус],Сводные!D2,PriceList[Площадь, кв.м]) +SUMIF(PriceList[Корпус],Сводные!E2,PriceList[Площадь, кв.м])) -> 364346.2
A10: корпус C2
A11: Кол-во спален | B11: Сред. площадь, кв. м | C11: Кол-во, шт. | D11: % | E11: Средневзв стартовая цена, руб.
A12: Ст | B12: {=AVERAGE( IF((PriceList[Количество комнат]=A12)* ((PriceList[Корпус]=$C$2)), PriceList[Площадь, кв.м] ) )} -> 31.370669 | C12: {=SUM( IF((PriceList[Количество комнат]=A5)* ((PriceList[Корпус]=$C$2)), 1) )} -> 314 | D12: =C12/$C$15 -> 0.94864048 | E12: {=SUMPRODUCT((PriceList[Комнат в шахматку]=A12)*((PriceList[Корпус]=$C$2))*PriceList[ИТОГ Бюджет, руб]) / SUMPRODUCT((PriceList[Комнат в шахматку]=A12)*((PriceList[Корпус]=$C$2))*PriceList[Площадь, кв.м])} -> 376656.95
A13: 1К | B13: {=AVERAGE( IF((PriceList[Количество комнат]=A13)* ((PriceList[Корпус]=$C$2)), PriceList[Площадь, кв.м] ) )} -> 61.362353 | C13: {=SUM( IF((PriceList[Количество комнат]=A6)* ((PriceList[Корпус]=$C$2)), 1) )} -> 17 | D13: =C13/$C$15 -> 0.051359517 | E13: {=SUMPRODUCT((PriceList[Комнат в шахматку]=A13)*((PriceList[Корпус]=$C$2))*PriceList[ИТОГ Бюджет, руб]) / SUMPRODUCT((PriceList[Комнат в шахматку]=A13)*((PriceList[Корпус]=$C$2))*PriceList[Площадь, кв.м])} -> 389374.54
A14: 2К | C14: {=SUM( IF((PriceList[Количество комнат]=A7)* ((PriceList[Корпус]=$C$2)), 1) )} -> 0 | D14: =C14/$C$15 -> 0
C15: =SUM(C12:C14) -> 331 | D15: =SUM(D12:D14) -> 1 | E15: =(SUMIF(PriceList[Корпус],C2,PriceList[ИТОГ Бюджет, руб]) ) / (SUMIF(PriceList[Корпус],C2,PriceList[Площадь, кв.м]) ) -> 377874.77
A18: Первая очередь строительства корпуса: С1, С2, С3 | C18: С2 и С4 (корпуса, которые отдаются под управление гостиничного оператора COSMOS, соответственно цены будут выше, чем основного объема)
A19: Старт первой очереди 15.10.2025 | C19: С5 (премиальный корпус, с дорогой отделкой, с более премиальными материалами и тд)
A20: Ввод в эксплуатацию: ноябрь 2029
A22: Кол-во месяцев продаж | B22: =COUNT(#REF!) -> 0
A23: % распроданности к вводу | B23: 1
A24: Темп продаж в месяц, шт. | B24: =(C15+C8)/B22 -> #DIV/0!
A28: 2 очередь | B28: 4 | C28: 5
A29: корпус С4 | E29: цены кв. м корпуса С4 приравнены ценам корпуса С2 1 очереди в марте 2026 за вычетом индексации, размер которой можно изменять
A30: Кол-во спален | B30: Сред. площадь, кв. м | C30: Кол-во, шт. | D30: % | E30: Средневзв стартовая цена, руб. | F30: индексация на старт 2 оч
A31: ст | B31: {=AVERAGE( IF( (Таблица1[Кол-во комнат]=A31)* (Таблица1[Корпус]=$B$28), Таблица1[Общая площадь с учетом летних помещений с коэф., кв.м] ) )} -> 31.65949 | C31: {=SUM( IF((Таблица1[Кол-во комнат]=A31)* ((Таблица1[Корпус]=$B$28)), 1) )} -> 314 | D31: =C31/$C$33 -> 0.94864048 | E31: =#REF!*(100%+F31) -> #REF! | F31: -0.01
A32: 1АЕ | B32: {=AVERAGE( IF( (Таблица1[Кол-во комнат]=A32)* (Таблица1[Корпус]=$B$28), Таблица1[Общая площадь с учетом летних помещений с коэф., кв.м] ) )} -> 61.72 | C32: {=SUM( IF((Таблица1[Кол-во комнат]=A32)* ((Таблица1[Корпус]=$B$28)), 1) )} -> 17 | D32: =C32/$C$33 -> 0.051359517 | E32: =#REF!*(100%+F32) -> #REF! | F32: -0.01
C33: =SUM(C31:C32) -> 331 | D33: =SUM(D31:D32) -> 1 | E33: =(#REF!+#REF!)/(#REF!+#REF!) -> #REF!
A35: корпус C5 | E35: цены кв. м корпуса С4 приравнены ценам корпуса С1,С3 1 очереди в марте 2026 за вычетом индексации, размер которой можно изменять
A36: Кол-во спален | B36: Сред. площадь, кв. м | C36: Кол-во, шт. | D36: % | E36: Средневзв стартовая цена, руб. | F36: индексация на старт 2 оч
A37: ст | B37: {=AVERAGE( IF( (Таблица1[Кол-во комнат]=A37)* (Таблица1[Корпус]=$C$28), Таблица1[Общая площадь с учетом летних помещений с коэф., кв.м] ) )} -> 39.767406 | C37: {=SUM( IF((Таблица1[Кол-во комнат]=A37)* ((Таблица1[Корпус]=$C$28)), 1) )} -> 239 | D37: =C37/$C$40 -> 0.76357827 | E37: =#REF!*(100%+F37) -> #REF! | F37: 0.03
A38: 1АЕ | B38: {=AVERAGE( IF( (Таблица1[Кол-во комнат]=A38)* (Таблица1[Корпус]=$C$28), Таблица1[Общая площадь с учетом летних помещений с коэф., кв.м] ) )} -> 64.328871 | C38: {=SUM( IF((Таблица1[Кол-во комнат]=A38)* ((Таблица1[Корпус]=$C$28)), 1) )} -> 62 | D38: =C38/$C$40 -> 0.19808307 | E38: =#REF!*(100%+F38) -> #REF! | F38: 0.03
A39: 2АЕ | B39: {=AVERAGE( IF( (Таблица1[Кол-во комнат]=A39)* (Таблица1[Корпус]=$C$28), Таблица1[Общая площадь с учетом летних помещений с коэф., кв.м] ) )} -> 100.18333 | C39: {=SUM( IF((Таблица1[Кол-во комнат]=A39)* ((Таблица1[Корпус]=$C$28)), 1) )} -> 12 | D39: =C39/$C$40 -> 0.038338658 | E39: =#REF!*(100%+F39) -> #REF! | F39: 0.03
C40: =SUM(C37:C39) -> 313 | D40: =SUM(D37:D39) -> 1 | E40: =(#REF!+#REF!+#REF!)/(#REF!+#REF!+#REF!) -> #REF!
A43: Вторая очередь строительства корпуса: С4, С5
A44: Старт продаж второй очереди: 01.03.2026
A45: Ввод в эксплуатацию: сентябрь 2030
A47: Кол-во месяцев продаж | B47: =COUNT(#REF!) -> 0
A48: % распроданности к вводу | B48: 1
A49: Темп продаж в месяц, шт. | B49: =(C40+C33)/B47 -> #DIV/0!

Sheet Доходность
A2: КАЛЬКУЛЯТОР ДОХОДНОСТИ
A3: Номер | B3: 120 | C3: необходимо выбрать из списка | D3: Рост цены
A4: В рассрочку | B4: нет | C4: необходимо выбрать из списка
A5: Этаж | B5: =VLOOKUP($B$3,'Реестр 1 оч '!$C$329:$BI$659,3,0) -> 4 | D5: Рост цены | F5: 0.15 | G5: 0.15 | H5: 0.15 | I5: 0.15 | J5: 0.02 | K5: =J5 -> 0.02 | L5: =K5 -> 0.02 | M5: =L5 -> 0.02 | N5: =M5 -> 0.02 | O5: =N5 -> 0.02 | P5: =O5 -> 0.02 | Q5: =P5 -> 0.02 | R5: =Q5 -> 0.02 | S5: =R5 -> 0.02
A6: площадь лота | B6: =VLOOKUP($B$3,'Реестр 1 оч '!$C$329:$BI$659,5,0) -> 28.53 | D6: год | E6: 2025 | F6: 2026 | G6: 2027 | H6: 2028 | I6: 2029 | J6: 2030 | K6: 2031 | L6: 2032 | M6: 2033 | N6: 2034 | O6: 2035 | P6: 2036 | Q6: 2037 | R6: 2038 | S6: 2039
A7: Тип апартамента | B7: =VLOOKUP($B$3,'Реестр 1 оч '!$C$329:$BI$659,12,0) -> S | D7: цена лота, руб | E7: =IF(B4="да",B11,B10) -> 11105302 | F7: =E7*F5+E7 -> 12771098 | G7: =F7*G5+F7 -> 14686763 | H7: =G7*H5+G7 -> 16889777 | I7: =H7*I5+H7 -> 19423243 | J7: =I7*J5+I7 -> 19811708 | K7: =J7*K5+J7 -> 20207943 | L7: =K7*L5+K7 -> 20612101 | M7: =L7*M5+L7 -> 21024343 | ... S7: =R7*S5+R7 -> 23676825
A8: Вид из окна | B8: =VLOOKUP($B$3,'Реестр 1 оч '!$C$329:$BI$659,17,0) -> Двор | D8: цена лота - цена покупки, руб | E8: =IF(B4="да",E7-B11,E7-B10) -> 0 | F8: =IF(C4="да",F7-$B$11,F7-$B$10) -> 1665795.4 | G8: =IF(D4="да",G7-$B$11,G7-$B$10) -> 3581460.1 | H8: =IF(E4="да",H7-$B$11,H7-$B$10) -> 5784474.4 | I8: =IF(F4="да",I7-$B$11,I7-$B$10) -> 8317941 | J8: =IF(G4="да",J7-$B$11,J7-$B$10) -> 8706405.9 | K8: =IF(H4="да",K7-$B$11,K7-$B$10) -> 9102640 | L8: =IF(I4="да",L7-$B$11,L7-$B$10) -> 9506798.9 | M8: =IF(J4="да",M7-$B$11,M7-$B$10) -> 9919040.9 | ... S8: =IF(P4="да",S7-$B$11,S7-$B$10) -> 12571523
A9: Цена кв. м на сайте | B9: =VLOOKUP($B$3,'Реестр 1 оч '!$C$329:$BI$659,59,0) -> 432500
A10: Цена лота при 100% оплате | B10: =VLOOKUP($B$3,'Реестр 1 оч '!$C$329:$BM$659,63,0) -> 11105302
A11: Цена лота при рассрочке | B11: =VLOOKUP($B$3,'Реестр 1 оч '!$C$329:$BM$659,57,0) -> 12339225
A12: Дата передачи ключей | B12: 47423
A13: Рост цены к передаче ключей | B13: =IF(B4="да",(I7-B11)/B11,(I7-B10)/B10) -> 0.74900625
A14: Цена лота к передаче ключей | B14: =B10+B10*B13 -> 19423243
A15: Цена кв.м. к передаче ключей | B15: =B14/B6 -> 680800.68
A16: Доход от роста цены к передаче ключей | B16: =IF(B4="да",B14-B11,B14-B10) -> 8317941
A18: Цена к 2039 году | B18: =S7 -> 23676825
A19: Доход от роста цены к 2039 году | B19: =IF(B4="да",S7-B11,S7-B10) -> 12571523
A21: Доход от отеля за 10 лет | B21: =SUM(E38:N38) -> 23177598
A22: Средняя годовая прибыль от отеля | B22: =B19/10 -> 1257152.3
A23: Среднегодовой доход от отеля в % | B23: =IF(B4="да", B21/B11/10,B21/B11/10) -> 0.18783674
A25: Совокупный доход (аренда + рост цены) | B25: =B21+B19 -> 35749121
A26: Средняя годовой доход общий (аренды + рост цены) | B26: =B25/10 -> 3574912.1
A27: Среднегодовой доход общий за 10 лет в % | B27: =IF(B4="да",B25/B11/10,B25/B10/10) -> 0.32191037 | E27: 2030 | F27: 2031 | G27: 2032 | H27: 2033 | I27: 2034 | J27: 2035 | K27: 2036 | L27: 2037 | M27: 2038 | N27: 2039
D28: Количество дней | E28: 365 | F28: 365 | G28: 365 | H28: 365 | I28: 365 | J28: 365 | K28: 365 | L28: 365 | M28: 365 | N28: 365
A29: Срок окупаемости за счет доходов от отеля и продажи, лет | B29: {=IF(B4="да",(MATCH(TRUE,$E$43:$N$43+$J$8:$S$8>=$B$11,0)),(MATCH(TRUE,$E$43:$N$43+$J$8:$S$8>=$B$10,0)))} -> 2 | D29: Загрузка | E29: 0.35 | F29: 0.44 | G29: 0.59 | H29: 0.65 | I29: 0.65 | J29: 0.65 | K29: 0.65 | L29: 0.65 | M29: 0.65 | N29: 0.65
A30: Срок окупаемости только за счет доходов от отеля, лет | B30: {=IF(B4="да",(MATCH(TRUE,$E$43:$N$43>=$B$11,0)),(MATCH(TRUE,$E$43:$N$43>=$B$10,0)))} -> 7 | D30: Открытая цена на рынке, руб | E30: =E31 -> 18000 | F30: =F31 -> 19440 | G30: =G31 -> 20995.2 | H30: =H31 -> 22674.816 | I30: =I31 -> 24488.801 | J30: =J31 -> 26447.905 | K30: =K31 -> 28563.738 | L30: =L31 -> 30848.837 | M30: =M31 -> 33316.744 | N30: =M31+M31*$B$48 -> 35982.083
D31: ADR (для расчета) | E31: =SUM(E32:E35) -> 18000 | F31: =F32+F33+F34+F35 -> 19440 | G31: =G32+G33+G34+G35 -> 20995.2 | H31: =H32+H33+H34+H35 -> 22674.816 | I31: =I32+I33+I34+I35 -> 24488.801 | J31: =J32+J33+J34+J35 -> 26447.905 | K31: =K32+K33+K34+K35 -> 28563.738 | L31: =L32+L33+L34+L35 -> 30848.837 | M31: =L31+L31*$B$48 -> 33316.744 | N31: =M31+M31*$B$48 -> 35982.083
D32: в т.ч. Размещение | E32: =INDEX(E46:I469, MATCH($B7,$E$47:$E$51,0),MATCH($B8,$F$46:$I$46,0)) -> 14400 | F32: =E32+E32*$B$48 -> 15552 | G32: =F32+F32*$B$48 -> 16796.16 | H32: =G32+G32*$B$48 -> 18139.853 | I32: =H32+H32*$B$48 -> 19591.041 | J32: =I32+I32*$B$48 -> 21158.324 | K32: =J32+J32*$B$48 -> 22850.99 | L32: =K32+K32*$B$48 -> 24679.069 | M32: =L32+L32*$B$48 -> 26653.395 | N32: =M32+M32*$B$48 -> 28785.667
D33: в т.ч. Завтрак | E33: 3500 | F33: =E33+E33*$B$48 -> 3780 | G33: =F33+F33*$B$48 -> 4082.4 | H33: =G33+G33*$B$48 -> 4408.992 | I33: =H33+H33*$B$48 -> 4761.7114 | J33: =I33+I33*$B$48 -> 5142.6483 | K33: =J33+J33*$B$48 -> 5554.0601 | L33: =K33+K33*$B$48 -> 5998.3849 | M33: =L33+L33*$B$48 -> 6478.2557 | N33: =M33+M33*$B$48 -> 6996.5162
D34: в т.ч. Детская комната | E34: 50 | F34: =E34+E34*$B$48 -> 54 | G34: =F34+F34*$B$48 -> 58.32 | H34: =G34+G34*$B$48 -> 62.9856 | I34: =H34+H34*$B$48 -> 68.024448 | J34: =I34+I34*$B$48 -> 73.466404 | K34: =J34+J34*$B$48 -> 79.343716 | L34: =K34+K34*$B$48 -> 85.691213 | M34: =L34+L34*$B$48 -> 92.546511 | N34: =M34+M34*$B$48 -> 99.950231
A35: Проживание собственника | D35: в т.ч.Коворкинг | E35: 50 | F35: =E35+E35*$B$48 -> 54 | G35: =F35+F35*$B$48 -> 58.32 | H35: =G35+G35*$B$48 -> 62.9856 | I35: =H35+H35*$B$48 -> 68.024448 | J35: =I35+I35*$B$48 -> 73.466404 | K35: =J35+J35*$B$48 -> 79.343716 | L35: =K35+K35*$B$48 -> 85.691213 | M35: =L35+L35*$B$48 -> 92.546511 | N35: =M35+M35*$B$48 -> 99.950231
A36: 20% скидка вне зависимости от сезона в любом апартаменте | D36: Валовая выручка | E36: =E31*E28*E29 -> 2299500 | F36: =F31*F28*F29 -> 3122064 | G36: =G31*G28*G29 -> 4521316.3 | H36: =H31*H28*H29 -> 5379600.1 | I36: =I31*I28*I29 -> 5809968.1 | J36: =J31*J28*J29 -> 6274765.6 | K36: =K31*K28*K29 -> 6776746.8 | L36: =L31*L28*L29 -> 7318886.5 | ... N36: =N31*N28*N29 -> 8536749.3
A37: вне зависимости от его категории, но не более 21 дня | D37: Валовая выручка за размещение | E37: =E28*E32*E29 -> 1839600 | F37: =F28*F32*F29 -> 2497651.2 | G37: =G28*G32*G29 -> 3617053.1 | H37: =H28*H32*H29 -> 4303680.1 | I37: =I28*I32*I29 -> 4647974.5 | J37: =J28*J32*J29 -> 5019812.4 | K37: =K28*K32*K29 -> 5421397.4 | L37: =L28*L32*L29 -> 5855109.2 | ... N37: =N28*N32*N29 -> 6829399.4
D38: Расходы на управления 50% | E38: =E37*$B$47 -> 919800 | F38: =F37*$B$47 -> 1248825.6 | G38: =G37*$B$47 -> 1808526.5 | H38: =H37*$B$47 -> 2151840 | I38: =I37*$B$47 -> 2323987.2 | J38: =J37*$B$47 -> 2509906.2 | K38: =K37*$B$47 -> 2710698.7 | L38: =L37*$B$47 -> 2927554.6 | ... N38: =N37*$B$47 -> 3414699.7
D39: Доход собственника от отеля | E39: =E37-E38 -> 919800 | F39: =F37-F38 -> 1248825.6 | G39: =G37-G38 -> 1808526.5 | H39: =H37-H38 -> 2151840 | I39: =I37-I38 -> 2323987.2 | J39: =J37-J38 -> 2509906.2 | K39: =K37-K38 -> 2710698.7 | L39: =L37-L38 -> 2927554.6 | ... N39: =N37-N38 -> 3414699.7
D40: Ежемесячный доход собственника апартамента | E40: =E39/12 -> 76650 | F40: =F39/12 -> 104068.8 | G40: =G39/12 -> 150710.54 | H40: =H39/12 -> 179320 | I40: =I39/12 -> 193665.6 | J40: =J39/12 -> 209158.85 | K40: =K39/12 -> 225891.56 | L40: =L39/12 -> 243962.88 | ... N40: =N39/12 -> 284558.31
D41: Ежемесячный доход собственника детской комнаты и коворкинга с учетом расхода 35% | E41: =(E35+E34)*E28*E29/12*319*0.65 -> 220741.35 | F41: =(F35+F34)*F28*F29/12*319*0.65 -> 299703.69 | G41: =(G35+G34)*G28*G29/12*319*0.65 -> 434025.43 | H41: =(H35+H34)*H28*H29/12*319*0.65 -> 516416.7 | I41: =(I35+I34)*I28*I29/12*319*0.65 -> 557730.04 | J41: =(J35+J34)*J28*J29/12*319*0.65 -> 602348.44 | K41: =(K35+K34)*K28*K29/12*319*0.65 -> 650536.32 | L41: =(L35+L34)*L28*L29/12*319*0.65 -> 702579.22 | ... N41: =(N35+N34)*N28*N29/12*319*0.65 -> 819488.41
D42: Годовая доходность, % | E42: =IF($B$4="да",E39/$B$11,E39/$B$10) -> 0.082825299 | F42: =IF($B$4="да",F39/$B$11,F39/$B$10) -> 0.11245309 | G42: =IF($B$4="да",G39/$B$11,G39/$B$10) -> 0.16285252 | H42: =IF($B$4="да",H39/$B$11,H39/$B$10) -> 0.1937669 | I42: =IF($B$4="да",I39/$B$11,I39/$B$10) -> 0.20926825 | J42: =IF($B$4="да",J39/$B$11,J39/$B$10) -> 0.22600971 | K42: =IF($B$4="да",K39/$B$11,K39/$B$10) -> 0.24409049 | L42: =IF($B$4="да",L39/$B$11,L39/$B$10) -> 0.26361773 | ... N42: =IF($B$4="да",N39/$B$11,N39/$B$10) -> 0.30748372
D43: Накопленный доход собственника | E43: =E39 -> 919800 | F43: =E43+F39 -> 2168625.6 | G43: =F43+G39 -> 3977152.1 | H43: =G43+H39 -> 6128992.2 | I43: =H43+I39 -> 8452979.4 | J43: =I43+J39 -> 10962886 | K43: =J43+K39 -> 13673584 | L43: =K43+L39 -> 16601139 | M43: =L43+M39 -> 19762898 | N43: =M43+N39 -> 23177598
A45: 47423 | B45: ДАТА РВ | E45: ADR | G45: 0.03 | H45: 0.03 | I45: 0.03
...

Sheet check
F2: проверка с итогами | I2: сверка с итогами по ценам
A3: Корпус2 | B3: КК | C3: Кол-во | D3: Площадь | L3: Корпус2 | M3: КК | N3: Average of Площадь, кв.м | O3: Площадь | P3: Sum of ИТОГ Бюджет, руб
A4: Group1 | B4: Ст | C4: 593 | D4: 19157.55 | F4: =C4=#REF! -> #REF! | L4: Group1 | M4: Ст | N4: 32.306155 | O4: 19157.55 | P4: 6.8674513e+09 | Q4: =P4/O4 -> 358472.31 | R4: =Q4=Сводные!E5 -> FALSE | T4: =N4=Сводные!B5 -> TRUE | U4: =N4=#REF! -> #REF!
B5: 1К | C5: 77 | D5: 4457.67 | F5: =C5=#REF! -> #REF! | M5: 1К | N5: 57.891818 | O5: 4457.67 | P5: 1.5824629e+09 | Q5: =P5/O5 -> 354997.77 | R5: =Q5=Сводные!E6 -> FALSE | T5: =N5=Сводные!B6 -> TRUE | U5: =GETPIVOTDATA("Average of Площадь, кв.м",$L$3,"КК","1К","Корпус2","Group1")=#REF! -> #REF!
B6: 2К | C6: 1 | D6: 82.76 | F6: =C6=#REF! -> #REF! | M6: 2К | N6: 82.76 | O6: 82.76 | P6: 33813750 | Q6: =P6/O6 -> 408576 | R6: =Q6=Сводные!E7 -> FALSE | T6: =N6=Сводные!B7 -> TRUE | U6: =GETPIVOTDATA("Average of Площадь, кв.м",$L$3,"КК","2К","Корпус2","Group1")=#REF! -> #REF!
A7: Group1 Total | C7: 671 | D7: 23697.98 | L7: Group1 Total | N7: 35.317407 | O7: 23697.98 | P7: 8.4837279e+09 | Q7: =P7/O7 -> 357993.72
A8: С2 | B8: Ст | C8: 314 | D8: 9850.39 | F8: =C8=#REF! -> #REF! | L8: С2 | M8: Ст | N8: 31.370669 | O8: 9850.39 | P8: 3.4558134e+09 | Q8: =P8/O8 -> 350830.11 | R8: =Q8=Сводные!E12 -> FALSE | T8: =N8=Сводные!B12 -> TRUE | U8: =N8=#REF! -> #REF!
B9: 1К | C9: 17 | D9: 1043.16 | F9: =C9=#REF! -> #REF! | M9: 1К | N9: 61.362353 | O9: 1043.16 | P9: 3.6345836e+08 | Q9: =P9/O9 -> 348420.53 | R9: =Q9=Сводные!E13 -> FALSE | T9: =N9=Сводные!B13 -> TRUE | U9: =GETPIVOTDATA("Average of Площадь, кв.м",$L$3,"КК","1К","Корпус2","С2")=#REF! -> #REF!
A10: С2 Total | C10: 331 | D10: 10893.55 | L10: С2 Total | N10: 32.911027 | O10: 10893.55 | P10: 3.8192718e+09 | Q10: =P10/O10 -> 350599.37 | R10: =Q10=Сводные!E15 -> FALSE
A11: Grand Total | C11: 1002 | D11: 34591.53 | F11: =C11=#REF! -> #REF! | L11: Grand Total | N11: 34.522485 | O11: 34591.53 | P11: 1.2303e+10 | Q11: =P11/O11 -> 355665.09
A15: Корпус | B15: Кол-во комнат | C15: Кол-во | D15: Площадь
A16: 4 | B16: ст | C16: 314 | D16: 9941.08 | F16: =C16=#REF! -> #REF!
B17: 1АЕ | C17: 17 | D17: 1049.24 | F17: =C17=#REF! -> #REF! | L17: Корпус | M17: Кол-во комнат | N17: Средняя | O17: Площадь
A18: 4 Total | C18: 331 | D18: 10990.32 | L18: 4 | M18: ст | N18: 31.65949 | O18: 9941.08 | Q18: =N18=Сводные!B31 -> TRUE | R18: =GETPIVOTDATA("Средняя",$L$17,"Корпус",4,"Кол-во комнат","ст")=#REF! -> #REF!
A19: 5 | B19: ст | C19: 239 | D19: 9504.41 | F19: =C19=#REF! -> #REF! | M19: 1АЕ | N19: 61.72 | O19: 1049.24 | Q19: =GETPIVOTDATA("Средняя",$L$17,"Корпус",4,"Кол-во комнат","1АЕ")=Сводные!B32 -> TRUE | R19: =GETPIVOTDATA("Средняя",$L$17,"Корпус",4,"Кол-во комнат","1АЕ")=#REF! -> #REF!
B20: 1АЕ | C20: 62 | D20: 3988.39 | F20: =C20=#REF! -> #REF! | L20: 4 Total | N20: 33.203384 | O20: 10990.32
B21: 2АЕ | C21: 12 | D21: 1202.2 | F21: =C21=#REF! -> #REF! | L21: 5 | M21: ст | N21: 39.767406 | O21: 9504.41 | Q21: =GETPIVOTDATA("Средняя",$L$17,"Корпус",5,"Кол-во комнат","ст")=Сводные!B37 -> TRUE | R21: =#REF!=GETPIVOTDATA("Средняя",check!$L$17,"Корпус",5,"Кол-во комнат","ст") -> #REF!
A22: 5 Total | C22: 313 | D22: 14695 | M22: 1АЕ | N22: 64.328871 | O22: 3988.39 | Q22: =GETPIVOTDATA("Средняя",$L$17,"Корпус",5,"Кол-во комнат","1АЕ")=Сводные!B38 -> TRUE | R22: =GETPIVOTDATA("Средняя",$L$17,"Корпус",5,"Кол-во комнат","1АЕ")=#REF! -> #REF!
A23: Grand Total | C23: 644 | D23: 25685.32 | M23: 2АЕ | N23: 100.18333 | O23: 1202.2 | Q23: =GETPIVOTDATA("Средняя",$L$17,"Корпус",5,"Кол-во комнат","2АЕ")=Сводные!B39 -> TRUE | R23: =GETPIVOTDATA("Средняя",$L$17,"Корпус",5,"Кол-во комнат","2АЕ")=#REF! -> #REF!
L24: 5 Total | N24: 46.948882 | O24: 14695
L25: Grand Total | N25: 39.884037 | O25: 25685.32
N29: =#REF!*(100%+Сводные!F31) -> #REF!

Sheet Реестр 1 оч 
A1: Отчет о выполненных работах к приложению №13 к Договору от 17.06.2025 № ДОМУ/2025-06/17 от ИП СИЗОВА ВП | AZ1: 500 | BA1: ДЛЯ САЙТА | BD1: ФИНАЛЬНАЯ ЦЕНА ДЛЯ ЗАГРУЗКИ | BG1: =AO3 -> 6000 | BI1: ПРОВЕРКА - НЕ БЕРЕМ В ЗАЛИВКУ
A2: № п/п | B2: Код ОН | C2: Условный номер | D2: Корпус | E2: Этаж | F2: Номер на площадке | G2: Площадь, кв.м | H2: Количество комнат | I2: Тип по АР | J2: Площадь летних помещений | K2: Площадь летних помещений с коэф. 0,3 | L2: Площадь без летних помещений, кв.м | M2: Площадь с коэф, кв.м | N2: Размер | O2: Тип планировки | P2: Геометрия | Q2: Удленность от лифта (входа) | R2: Виды | S2: Виды для CRM | T2: Расположение на этаже | U2: Количество лотов на этаже | V2: Базовая цена за кв.м, руб (до поправок) | W2: Поправка на этаж, % | X2: Поправка на размер, % | Y2: Поправка на тип планировки, % | Z2: Поправка геометрию, % | AA2: Поправка на удаленность от лифта (входа), % | AB2: Поправка на виды, % | AC2: Поправка на расположение на этаже, % | AD2: Поправка на количество лотов на этаже, % | AE2: Поправка на корпус, % | AF2: РАСЦЕНКА Цена за кв.м, руб | AG2: РАСЦЕНКА Бюджет, руб | AH2: Повышение цены, скидка | AI2: ИТОГ Цена за кв.м, руб | AJ2: ИТОГ Бюджет, руб | AK2: СТАТУС | AL2: Максимальная скидка | AM2: Цена за кв.м. в CRM | AN2: Стоимость, руб для CRM | AO2: Бронь | AP2: Цена за кв.м. в сайт | AQ2: Стоимость, руб для сбронированием | AR2: Код ОН для шахиатки | AS2: Комнат в шахматку | AT2: Площадь в шахматку | AU2: Цена в шахматку | AV2: СТАТУС В ШАХМАТКУ | AW2: Комментарий | AX2: Столбец1 | AZ2: Цена за кв.м. с повышением 500 | BA2: Стоимость с учетом регистрации | BB2: разница | BD2: Цена за кв.м. с повышением 500 | BE2: Стоимость с учетом регистрации | BG2: Стоимость ДДУ | BH2: Бронь | BI2: Цена за кв.м. в ДДУ | BJ2: Процент брони | BL2: Цена со скидкой 10% | BM2: Стоимость лота со скидкой 10%
A3: 1 | B3: С1-1 | C3: 1 | D3: С1 | E3: 1 | F3: 1 | G3: 32.93 | H3: Ст | I3: Ст | J3: 8.19 | K3: =ROUND(J3*0.3,2) -> 2.46 | L3: =G3-J3 -> 24.74 | M3: =L3+K3 -> 27.2 | N3: S | O3: Линейная | P3: Правильная | Q3: Зона 1 | R3: Двор север | S3: Двор | T3: Около/над входной группой | U3: 13 | V3: =IFERROR(VLOOKUP(H3,'Коэфф для прайса 1 оч'!$A$3:$C$6,3,0),"") -> 327000 | W3: =IFERROR(VLOOKUP(E3,'Коэфф для прайса 1 оч'!$A$10:$C$23,3,0),"") -> -0.045 | X3: =IFERROR(VLOOKUP(N3,'Коэфф для прайса 1 оч'!$E$25:$F$30,2,0),"") -> 0.04 | Y3: =IFERROR(VLOOKUP(O3,'Коэфф для прайса 1 оч'!$E$32:$F$34,2,0),"") -> 0 | Z3: =IFERROR(VLOOKUP(P3,'Коэфф для прайса 1 оч'!$E$36:$F$38,2,0),"") -> 0.03 | AA3: =IFERROR(VLOOKUP(Q3,'Коэфф для прайса 1 оч'!$E$40:$F$43,2,0),"") -> 0.005 | AB3: =IFERROR(VLOOKUP(R3,'Коэфф для прайса 1 оч'!$E$45:$F$59,2,0),"") -> -0.015 | AC3: =IFERROR(VLOOKUP(T3,'Коэфф для прайса 1 оч'!$E$61:$F$67,2,0),"") -> -0.01 | AD3: =IFERROR(VLOOKUP(U3,'Коэфф для прайса 1 оч'!$E$69:$F$82,2,0),"") -> 0.013 | AE3: =IFERROR(VLOOKUP(PriceList[[#This Row],[Корпус]],'Коэфф для прайса 1 оч'!$I$10:$J$15,2,0),"") -> 0 | AF3: =ROUND(V3+(V3*SUM(W3:AE3)),2) -> 332886 | AG3: =AF3*G3 -> 10961936 | AH3: 0 | AI3: =AF3+AF3*AH3 -> 332886 | AJ3: =AI3*G3 -> 10961936 | AK3: Резерв | AL3: 0.1 | AM3: =PriceList[[#This Row],[ИТОГ Цена за кв.м, руб]]*(1+PriceList[[#This Row],[Максимальная скидка]]) -> 366174.6 | AN3: =PriceList[[#This Row],[Цена за кв.м. в CRM]]*PriceList[[#This Row],[Площадь, кв.м]] -> 12058130 | AO3: 6000 | AP3: =PriceList[[#This Row],[Цена за кв.м. в CRM]]+PriceList[[#This Row],[Бронь]] -> 372174.6 | AQ3: =PriceList[[#This Row],[Цена за кв.м. в сайт]]*PriceList[[#This Row],[Площадь, кв.м]] -> 12255710 | AR3: =B3 -> С1-1 | AS3: =H3 -> Ст | AT3: =G3 -> 32.93 | AU3: =PriceList[[#This Row],[Цена за кв.м. в CRM]] -> 366174.6 | AV3: =AK3 -> Резерв | AX3: Резерв | AZ3: =(PriceList[[#This Row],[Цена за кв.м. в сайт]])+$AZ$1 -> 372674.6 | BA3: =AZ3*PriceList[[#This Row],[Площадь, кв.м]] -> 12272175 | BB3: =BA3-PriceList[[#This Row],[Стоимость, руб для сбронированием]] -> 16465 | BD3: =MROUND(AZ3,100) -> 372700 | BE3: =BD3*PriceList[[#This Row],[Площадь, кв.м]] -> 12273011 | BG3: =BE3-$BG$1*PriceList[[#This Row],[Площадь, кв.м]] -> 12075431 | BH3: =BE3-BG3 -> 197580 | BI3: =BG3/PriceList[[#This Row],[Площадь, кв.м]] -> 366700 | BJ3: =BH3/BG3 -> 0.016362149
A4: 10 | B4: С1-10 | C4: 10 | D4: С1 | E4: 1 | F4: 10 | G4: 31.95 | H4: Ст | I4: Ст | J4: 6.96 | K4: =ROUND(J4*0.3,2) -> 2.09 | L4: =G4-J4 -> 24.99 | M4: =L4+K4 -> 27.08 | N4: S | O4: Линейная | P4: Правильная | Q4: Зона 1 | R4: Двор северо-восток | S4: Двор | T4: Стандарт | U4: 13 | V4: =IFERROR(VLOOKUP(H4,'Коэфф для прайса 1 оч'!$A$3:$C$6,3,0),"") -> 327000 | W4: =IFERROR(VLOOKUP(E4,'Коэфф для прайса 1 оч'!$A$10:$C$23,3,0),"") -> -0.045 | X4: =IFERROR(VLOOKUP(N4,'Коэфф для прайса 1 оч'!$E$25:$F$30,2,0),"") -> 0.04 | Y4: =IFERROR(VLOOKUP(O4,'Коэфф для прайса 1 оч'!$E$32:$F$34,2,0),"") -> 0 | Z4: =IFERROR(VLOOKUP(P4,'Коэфф для прайса 1 оч'!$E$36:$F$38,2,0),"") -> 0.03 | AA4: =IFERROR(VLOOKUP(Q4,'Коэфф для прайса 1 оч'!$E$40:$F$43,2,0),"") -> 0.005 | AB4: =IFERROR(VLOOKUP(R4,'Коэфф для прайса 1 оч'!$E$45:$F$59,2,0),"") -> -0.01 | AC4: =IFERROR(VLOOKUP(T4,'Коэфф для прайса 1 оч'!$E$61:$F$67,2,0),"") -> 0 | AD4: =IFERROR(VLOOKUP(U4,'Коэфф для прайса 1 оч'!$E$69:$F$82,2,0),"") -> 0.013 | AE4: =IFERROR(VLOOKUP(PriceList[[#This Row],[Корпус]],'Коэфф для прайса 1 оч'!$I$10:$J$15,2,0),"") -> 0 | AF4: =ROUND(V4+(V4*SUM(W4:AE4)),2) -> 337791 | AG4: =AF4*G4 -> 10792422 | AH4: 0 | AI4: =AF4+AF4*AH4 -> 337791 | AJ4: =AI4*G4 -> 10792422 | AK4: Свободно | AL4: 0.1 | AM4: =PriceList[[#This Row],[ИТОГ Цена за кв.м, руб]]*(1+PriceList[[#This Row],[Максимальная скидка]]) -> 371570.1 | AN4: =PriceList[[#This Row],[Цена за кв.м. в CRM]]*PriceList[[#This Row],[Площадь, кв.м]] -> 11871665 | AO4: 6000 | AP4: =PriceList[[#This Row],[Цена за кв.м. в CRM]]+PriceList[[#This Row],[Бронь]] -> 377570.1 | AQ4: =PriceList[[#This Row],[Цена за кв.м. в сайт]]*PriceList[[#This Row],[Площадь, кв.м]] -> 12063365 | AR4: =B4 -> С1-10 | AS4: =H4 -> Ст | AT4: =G4 -> 31.95 | AU4: =PriceList[[#This Row],[Цена за кв.м. в CRM]] -> 371570.1 | AV4: =AK4 -> Свободно | AX4: Свободно | AZ4: =(PriceList[[#This Row],[Цена за кв.м. в сайт]])+$AZ$1 -> 378070.1 | BA4: =AZ4*PriceList[[#This Row],[Площадь, кв.м]] -> 12079340 | BB4: =BA4-PriceList[[#This Row],[Стоимость, руб для сбронированием]] -> 15975 | BD4: =MROUND(AZ4,100) -> 378100 | BE4: =BD4*PriceList[[#This Row],[Площадь, кв.м]] -> 12080295 | BG4: =BE4-$BG$1*PriceList[[#This Row],[Площадь, кв.м]] -> 11888595 | BH4: =BE4-BG4 -> 191700 | BI4: =BG4/PriceList[[#This Row],[Площадь, кв.м]] -> 372100 | BJ4: =BH4/BG4 -> 0.016124698
A5: 100 | B5: С1-100 | C5: 100 | D5: С1 | E5: 4 | F5: 5 | G5: 29.24 | H5: Ст | I5: Ст | J5: 4.25 | K5: =ROUND(J5*0.3,2) -> 1.28 | L5: =G5-J5 -> 24.99 | M5: =L5+K5 -> 26.27 | N5: S | O5: Линейная | P5: Правильная | Q5: Зона 3 | R5: Двор север | S5: Двор | T5: Стандарт | U5: 42 | V5: =IFERROR(VLOOKUP(H5,'Коэфф для прайса 1 оч'!$A$3:$C$6,3,0),"") -> 327000 | W5: =IFERROR(VLOOKUP(E5,'Коэфф для прайса 1 оч'!$A$10:$C$23,3,0),"") -> 0 | X5: =IFERROR(VLOOKUP(N5,'Коэфф для прайса 1 оч'!$E$25:$F$30,2,0),"") -> 0.04 | Y5: =IFERROR(VLOOKUP(O5,'Коэфф для прайса 1 оч'!$E$32:$F$34,2,0),"") -> 0 | Z5: =IFERROR(VLOOKUP(P5,'Коэфф для прайса 1 оч'!$E$36:$F$38,2,0),"") -> 0.03 | AA5: =IFERROR(VLOOKUP(Q5,'Коэфф для прайса 1 оч'!$E$40:$F$43,2,0),"") -> -0.005 | AB5: =IFERROR(VLOOKUP(R5,'Коэфф для прайса 1 оч'!$E$45:$F$59,2,0),"") -> -0.015 | AC5: =IFERROR(VLOOKUP(T5,'Коэфф для прайса 1 оч'!$E$61:$F$67,2,0),"") -> 0 | AD5: =IFERROR(VLOOKUP(U5,'Коэфф для прайса 1 оч'!$E$69:$F$82,2,0),"") -> -0.016 | AE5: =IFERROR(VLOOKUP(PriceList[[#This Row],[Корпус]],'Коэфф для прайса 1 оч'!$I$10:$J$15,2,0),"") -> 0 | AF5: =ROUND(V5+(V5*SUM(W5:AE5)),2) -> 338118 | AG5: =AF5*G5 -> 9886570.3 | AH5: 0 | AI5: =AF5+AF5*AH5 -> 338118 | AJ5: =AI5*G5 -> 9886570.3 | AK5: Свободно | AL5: 0.1 | AM5: =PriceList[[#This Row],[ИТОГ Цена за кв.м, руб]]*(1+PriceList[[#This Row],[Максимальная скидка]]) -> 371929.8 | AN5: =PriceList[[#This Row],[Цена за кв.м. в CRM]]*PriceList[[#This Row],[Площадь, кв.м]] -> 10875227 | AO5: 6000 | AP5: =PriceList[[#This Row],[Цена за кв.м. в CRM]]+PriceList[[#This Row],[Бронь]] -> 377929.8 | AQ5: =PriceList[[#This Row],[Цена за кв.м. в сайт]]*PriceList[[#This Row],[Площадь, кв.м]] -> 11050667 | AR5: =B5 -> С1-100 | AS5: =H5 -> Ст | AT5: =G5 -> 29.24 | AU5: =PriceList[[#This Row],[Цена за кв.м. в CRM]] -> 371929.8 | AV5: =AK5 -> Свободно | AX5: Бронь | AZ5: =(PriceList[[#This Row],[Цена за кв.м. в сайт]])+$AZ$1 -> 378429.8 | BA5: =AZ5*PriceList[[#This Row],[Площадь, кв.м]] -> 11065287 | BB5: =BA5-PriceList[[#This Row],[Стоимость, руб для сбронированием]] -> 14620 | BD5: =MROUND(AZ5,100) -> 378400 | BE5: =BD5*PriceList[[#This Row],[Площадь, кв.м]] -> 11064416 | BG5: =BE5-$BG$1*PriceList[[#This Row],[Площадь, кв.м]] -> 10888976 | BH5: =BE5-BG5 -> 175440 | BI5: =BG5/PriceList[[#This Row],[Площадь, кв.м]] -> 372400 | BJ5: =BH5/BG5 -> 0.016111708
A6: 101 | B6: С1-101 | C6: 101 | D6: С1 | E6: 4 | F6: 6 | G6: 29.24 | H6: Ст | I6: Ст | J6: 4.25 | K6: =ROUND(J6*0.3,2) -> 1.28 | L6: =G6-J6 -> 24.99 | M6: =L6+K6 -> 26.27 | N6: S | O6: Линейная | P6: Правильная | Q6: Зона 3 | R6: Двор север | S6: Двор | T6: Стандарт | U6: 42 | V6: =IFERROR(VLOOKUP(H6,'Коэфф для прайса 1 оч'!$A$3:$C$6,3,0),"") -> 327000 | W6: =IFERROR(VLOOKUP(E6,'Коэфф для прайса 1 оч'!$A$10:$C$23,3,0),"") -> 0 | X6: =IFERROR(VLOOKUP(N6,'Коэфф для прайса 1 оч'!$E$25:$F$30,2,0),"") -> 0.04 | Y6: =IFERROR(VLOOKUP(O6,'Коэфф для прайса 1 оч'!$E$32:$F$34,2,0),"") -> 0 | Z6: =IFERROR(VLOOKUP(P6,'Коэфф для прайса 1 оч'!$E$36:$F$38,2,0),"") -> 0.03 | AA6: =IFERROR(VLOOKUP(Q6,'Коэфф для прайса 1 оч'!$E$40:$F$43,2,0),"") -> -0.005 | AB6: =IFERROR(VLOOKUP(R6,'Коэфф для прайса 1 оч'!$E$45:$F$59,2,0),"") -> -0.015 | AC6: =IFERROR(VLOOKUP(T6,'Коэфф для прайса 1 оч'!$E$61:$F$67,2,0),"") -> 0 | AD6: =IFERROR(VLOOKUP(U6,'Коэфф для прайса 1 оч'!$E$69:$F$82,2,0),"") -> -0.016 | AE6: =IFERROR(VLOOKUP(PriceList[[#This Row],[Корпус]],'Коэфф для прайса 1 оч'!$I$10:$J$15,2,0),"") -> 0 | AF6: =ROUND(V6+(V6*SUM(W6:AE6)),2) -> 338118 | AG6: =AF6*G6 -> 9886570.3 | AH6: 0 | AI6: =AF6+AF6*AH6 -> 338118 | AJ6: =AI6*G6 -> 9886570.3 | AK6: Свободно | AL6: 0.1 | AM6: =PriceList[[#This Row],[ИТОГ Цена за кв.м, руб]]*(1+PriceList[[#This Row],[Максимальная скидка]]) -> 371929.8 | AN6: =PriceList[[#This Row],[Цена за кв.м. в CRM]]*PriceList[[#This Row],[Площадь, кв.м]] -> 10875227 | AO6: 6000 | AP6: =PriceList[[#This Row],[Цена за кв.м. в CRM]]+PriceList[[#This Row],[Бронь]] -> 377929.8 | AQ6: =PriceList[[#This Row],[Цена за кв.м. в сайт]]*PriceList[[#This Row],[Площадь, кв.м]] -> 11050667 | AR6: =B6 -> С1-101 | AS6: =H6 -> Ст | AT6: =G6 -> 29.24 | AU6: =PriceList[[#This Row],[Цена за кв.м. в CRM]] -> 371929.8 | AV6: =AK6 -> Свободно | AX6: Продано | AZ6: =(PriceList[[#This Row],[Цена за кв.м. в сайт]])+$AZ$1 -> 378429.8 | BA6: =AZ6*PriceList[[#This Row],[Площадь, кв.м]] -> 11065287 | BB6: =BA6-PriceList[[#This Row],[Стоимость, руб для сбронированием]] -> 14620 | BD6: =MROUND(AZ6,100) -> 378400 | BE6: =BD6*PriceList[[#This Row],[Площадь, кв.м]] -> 11064416 | BG6: =BE6-$BG$1*PriceList[[#This Row],[Площадь, кв.м]] -> 10888976 | BH6: =BE6-BG6 -> 175440 | BI6: =BG6/PriceList[[#This Row],[Площадь, кв.м]] -> 372400 | BJ6: =BH6/BG6 -> 0.016111708
A7: 102 | B7: С1-102 | C7: 102 | D7: С1 | E7: 4 | F7: 7 | G7: 28.6 | H7: Ст | I7: Ст | J7: 4.25 | K7: =ROUND(J7*0.3,2) -> 1.28 | L7: =G7-J7 -> 24.35 | M7: =L7+K7 -> 25.63 | N7: S | O7: Линейная | P7: Правильная | Q7: Зона 3 | R7: Двор север | S7: Двор | T7: Стандарт | U7: 42 | V7: =IFERROR(VLOOKUP(H7,'Коэфф для прайса 1 оч'!$A$3:$C$6,3,0),"") -> 327000 | W7: =IFERROR(VLOOKUP(E7,'Коэфф для прайса 1 оч'!$A$10:$C$23,3,0),"") -> 0 | X7: =IFERROR(VLOOKUP(N7,'Коэфф для прайса 1 оч'!$E$25:$F$30,2,0),"") -> 0.04 | Y7: =IFERROR(VLOOKUP(O7,'Коэфф для прайса 1 оч'!$E$32:$F$34,2,0),"") -> 0 | Z7: =IFERROR(VLOOKUP(P7,'Коэфф для прайса 1 оч'!$E$36:$F$38,2,0),"") -> 0.03 | AA7: =IFERROR(VLOOKUP(Q7,'Коэфф для прайса 1 оч'!$E$40:$F$43,2,0),"") -> -0.005 | AB7: =IFERROR(VLOOKUP(R7,'Коэфф для прайса 1 оч'!$E$45:$F$59,2,0),"") -> -0.015 | AC7: =IFERROR(VLOOKUP(T7,'Коэфф для прайса 1 оч'!$E$61:$F$67,2,0),"") -> 0 | AD7: =IFERROR(VLOOKUP(U7,'Коэфф для прайса 1 оч'!$E$69:$F$82,2,0),"") -> -0.016 | AE7: =IFERROR(VLOOKUP(PriceList[[#This Row],[Корпус]],'Коэфф для прайса 1 оч'!$I$10:$J$15,2,0),"") -> 0 | AF7: =ROUND(V7+(V7*SUM(W7:AE7)),2) -> 338118 | AG7: =AF7*G7 -> 9670174.8 | AH7: 0 | AI7: =AF7+AF7*AH7 -> 338118 | AJ7: =AI7*G7 -> 9670174.8 | AK7: Резерв | AL7: 0.1 | AM7: =PriceList[[#This Row],[ИТОГ Цена за кв.м, руб]]*(1+PriceList[[#This Row],[Максимальная скидка]]) -> 371929.8 | AN7: =PriceList[[#This Row],[Цена за кв.м. в CRM]]*PriceList[[#This Row],[Площадь, кв.м]] -> 10637192 | AO7: 6000 | AP7: =PriceList[[#This Row],[Цена за кв.м. в CRM]]+PriceList[[#This Row],[Бронь]] -> 377929.8 | AQ7: =PriceList[[#This Row],[Цена за кв.м. в сайт]]*PriceList[[#This Row],[Площадь, кв.м]] -> 10808792 | AR7: =B7 -> С1-102 | AS7: =H7 -> Ст | AT7: =G7 -> 28.6 | AU7: =PriceList[[#This Row],[Цена за кв.м. в CRM]] -> 371929.8 | AV7: =AK7 -> Резерв | AX7: Не для продажи | AZ7: =(PriceList[[#This Row],[Цена за кв.м. в сайт]])+$AZ$1 -> 378429.8 | BA7: =AZ7*PriceList[[#This Row],[Площадь, кв.м]] -> 10823092 | BB7: =BA7-PriceList[[#This Row],[Стоимость, руб для сбронированием]] -> 14300 | BD7: =MROUND(AZ7,100) -> 378400 | BE7: =BD7*PriceList[[#This Row],[Площадь, кв.м]] -> 10822240 | BG7: =BE7-$BG$1*PriceList[[#This Row],[Площадь, кв.м]] -> 10650640 | BH7: =BE7-BG7 -> 171600 | BI7: =BG7/PriceList[[#This Row],[Площадь, кв.м]] -> 372400 | BJ7: =BH7/BG7 -> 0.016111708
A8: 103 | B8: С1-103 | C8: 103 | D8: С1 | E8: 4 | F8: 8 | G8: 49.71 | H8: Ст | I8: Ст | J8: 13.98 | K8: =ROUND(J8*0.3,2) -> 4.19 | L8: =G8-J8 -> 35.73 | M8: =L8+K8 -> 39.92 | N8: L | O8: Угловая | P8: Правильная | Q8: Зона 3 | R8: Двор северо-восток | S8: Двор | T8: Стандарт | U8: 42 | V8: =IFERROR(VLOOKUP(H8,'Коэфф для прайса 1 оч'!$A$3:$C$6,3,0),"") -> 327000 | W8: =IFERROR(VLOOKUP(E8,'Коэфф для прайса 1 оч'!$A$10:$C$23,3,0),"") -> 0 | X8: =IFERROR(VLOOKUP(N8,'Коэфф для прайса 1 оч'!$E$25:$F$30,2,0),"") -> -0.01 | Y8: =IFERROR(VLOOKUP(O8,'Коэфф для прайса 1 оч'!$E$32:$F$34,2,0),"") -> 0.03 | Z8: =IFERROR(VLOOKUP(P8,'Коэфф для прайса 1 оч'!$E$36:$F$38,2,0),"") -> 0.03 | AA8: =IFERROR(VLOOKUP(Q8,'Коэфф для прайса 1 оч'!$E$40:$F$43,2,0),"") -> -0.005 | AB8: =IFERROR(VLOOKUP(R8,'Коэфф для прайса 1 оч'!$E$45:$F$59,2,0),"") -> -0.01 | AC8: =IFERROR(VLOOKUP(T8,'Коэфф для прайса 1 оч'!$E$61:$F$67,2,0),"") -> 0 | AD8: =IFERROR(VLOOKUP(U8,'Коэфф для прайса 1 оч'!$E$69:$F$82,2,0),"") -> -0.016 | AE8: =IFERROR(VLOOKUP(PriceList[[#This Row],[Корпус]],'Коэфф для прайса 1 оч'!$I$10:$J$15,2,0),"") -> 0 | AF8: =ROUND(V8+(V8*SUM(W8:AE8)),2) -> 333213 | AG8: =AF8*G8 -> 16564018 | AH8: 0 | AI8: =AF8+AF8*AH8 -> 333213 | AJ8: =AI8*G8 -> 16564018 | AK8: Резерв | AL8: 0.1 | AM8: =PriceList[[#This Row],[ИТОГ Цена за кв.м, руб]]*(1+PriceList[[#This Row],[Максимальная скидка]]) -> 366534.3 | AN8: =PriceList[[#This Row],[Цена за кв.м. в CRM]]*PriceList[[#This Row],[Площадь, кв.м]] -> 18220420 | AO8: 6000 | AP8: =PriceList[[#This Row],[Цена за кв.м. в CRM]]+PriceList[[#This Row],[Бронь]] -> 372534.3 | AQ8: =PriceList[[#This Row],[Цена за кв.м. в сайт]]*PriceList[[#This Row],[Площадь, кв.м]] -> 18518680 | AR8: =B8 -> С1-103 | AS8: =H8 -> Ст | AT8: =G8 -> 49.71 | AU8: =PriceList[[#This Row],[Цена за кв.м. в CRM]] -> 366534.3 | AV8: =AK8 -> Резерв | AZ8: =(PriceList[[#This Row],[Цена за кв.м. в сайт]])+$AZ$1 -> 373034.3 | BA8: =AZ8*PriceList[[#This Row],[Площадь, кв.м]] -> 18543535 | BB8: =BA8-PriceList[[#This Row],[Стоимость, руб для сбронированием]] -> 24855 | BD8: =MROUND(AZ8,100) -> 373000 | BE8: =BD8*PriceList[[#This Row],[Площадь, кв.м]] -> 18541830 | BG8: =BE8-$BG$1*PriceList[[#This Row],[Площадь, кв.м]] -> 18243570 | BH8: =BE8-BG8 -> 298260 | BI8: =BG8/PriceList[[#This Row],[Площадь, кв.м]] -> 367000 | BJ8: =BH8/BG8 -> 0.016348774
A9: 104 | B9: С1-104 | C9: 104 | D9: С1 | E9: 4 | F9: 9 | G9: 49.71 | H9: Ст | I9: Ст | J9: 13.98 | K9: =ROUND(J9*0.3,2) -> 4.19 | L9: =G9-J9 -> 35.73 | M9: =L9+K9 -> 39.92 | N9: L | O9: Угловая | P9: Правильная | Q9: Зона 3 | R9: Море | S9: Море | T9: Стандарт | U9: 42 | V9: =IFERROR(VLOOKUP(H9,'Коэфф для прайса 1 оч'!$A$3:$C$6,3,0),"") -> 327000 | W9: =IFERROR(VLOOKUP(E9,'Коэфф для прайса 1 оч'!$A$10:$C$23,3,0),"") -> 0 | X9: =IFERROR(VLOOKUP(N9,'Коэфф для прайса 1 оч'!$E$25:$F$30,2,0),"") -> -0.01 | Y9: =IFERROR(VLOOKUP(O9,'Коэфф для прайса 1 оч'!$E$32:$F$34,2,0),"") -> 0.03 | Z9: =IFERROR(VLOOKUP(P9,'Коэфф для прайса 1 оч'!$E$36:$F$38,2,0),"") -> 0.03 | AA9: =IFERROR(VLOOKUP(Q9,'Коэфф для прайса 1 оч'!$E$40:$F$43,2,0),"") -> -0.005 | AB9: =IFERROR(VLOOKUP(R9,'Коэфф для прайса 1 оч'!$E$45:$F$59,2,0),"") -> 0.07 | AC9: =IFERROR(VLOOKUP(T9,'Коэфф для прайса 1 оч'!$E$61:$F$67,2,0),"") -> 0 | AD9: =IFERROR(VLOOKUP(U9,'Коэфф для прайса 1 оч'!$E$69:$F$82,2,0),"") -> -0.016 | AE9: =IFERROR(VLOOKUP(PriceList[[#This Row],[Корпус]],'Коэфф для прайса 1 оч'!$I$10:$J$15,2,0),"") -> 0 | AF9: =ROUND(V9+(V9*SUM(W9:AE9)),2) -> 359373 | AG9: =AF9*G9 -> 17864432 | AH9: 0 | AI9: =AF9+AF9*AH9 -> 359373 | AJ9: =AI9*G9 -> 17864432 | AK9: Резерв | AL9: 0.1 | AM9: =PriceList[[#This Row],[ИТОГ Цена за кв.м, руб]]*(1+PriceList[[#This Row],[Максимальная скидка]]) -> 395310.3 | AN9: =PriceList[[#This Row],[Цена за кв.м. в CRM]]*PriceList[[#This Row],[Площадь, кв.м]] -> 19650875 | AO9: 6000 | AP9: =PriceList[[#This Row],[Цена за кв.м. в CRM]]+PriceList[[#This Row],[Бронь]] -> 401310.3 | AQ9: =PriceList[[#This Row],[Цена за кв.м. в сайт]]*PriceList[[#This Row],[Площадь, кв.м]] -> 19949135 | AR9: =B9 -> С1-104 | AS9: =H9 -> Ст | AT9: =G9 -> 49.71 | AU9: =PriceList[[#This Row],[Цена за кв.м. в CRM]] -> 395310.3 | AV9: =AK9 -> Резерв | AZ9: =(PriceList[[#This Row],[Цена за кв.м. в сайт]])+$AZ$1 -> 401810.3 | BA9: =AZ9*PriceList[[#This Row],[Площадь, кв.м]] -> 19973990 | BB9: =BA9-PriceList[[#This Row],[Стоимость, руб для сбронированием]] -> 24855 | BD9: =MROUND(AZ9,100) -> 401800 | BE9: =BD9*PriceList[[#This Row],[Площадь, кв.м]] -> 19973478 | BG9: =BE9-$BG$1*PriceList[[#This Row],[Площадь, кв.м]] -> 19675218 | BH9: =BE9-BG9 -> 298260 | BI9: =BG9/PriceList[[#This Row],[Площадь, кв.м]] -> 395800 | BJ9: =BH9/BG9 -> 0.015159171
A10: 105 | B10: С1-105 | C10: 105 | D10: С1 | E10: 4 | F10: 10 | G10: 28.6 | H10: Ст | I10: Ст | J10: 4.25 | K10: =ROUND(J10*0.3,2) -> 1.28 | L10: =G10-J10 -> 24.35 | M10: =L10+K10 -> 25.63 | N10: S | O10: Линейная | P10: Правильная | Q10: Зона 3 | R10: Море | S10: Море | T10: Стандарт | U10: 42 | V10: =IFERROR(VLOOKUP(H10,'Коэфф для прайса 1 оч'!$A$3:$C$6,3,0),"") -> 327000 | W10: =IFERROR(VLOOKUP(E10,'Коэфф для прайса 1 оч'!$A$10:$C$23,3,0),"") -> 0 | X10: =IFERROR(VLOOKUP(N10,'Коэфф для прайса 1 оч'!$E$25:$F$30,2,0),"") -> 0.04 | Y10: =IFERROR(VLOOKUP(O10,'Коэфф для прайса 1 оч'!$E$32:$F$34,2,0),"") -> 0 | Z10: =IFERROR(VLOOKUP(P10,'Коэфф для прайса 1 оч'!$E$36:$F$38,2,0),"") -> 0.03 | AA10: =IFERROR(VLOOKUP(Q10,'Коэфф для прайса 1 оч'!$E$40:$F$43,2,0),"") -> -0.005 | AB10: =IFERROR(VLOOKUP(R10,'Коэфф для прайса 1 оч'!$E$45:$F$59,2,0),"") -> 0.07 | AC10: =IFERROR(VLOOKUP(T10,'Коэфф для прайса 1 оч'!$E$61:$F$67,2,0),"") -> 0 | AD10: =IFERROR(VLOOKUP(U10,'Коэфф для прайса 1 оч'!$E$69:$F$82,2,0),"") -> -0.016 | AE10: =IFERROR(VLOOKUP(PriceList[[#This Row],[Корпус]],'Коэфф для прайса 1 оч'!$I$10:$J$15,2,0),"") -> 0 | AF10: =ROUND(V10+(V10*SUM(W10:AE10)),2) -> 365913 | AG10: =AF10*G10 -> 10465112 | AH10: 0 | AI10: =AF10+AF10*AH10 -> 365913 | AJ10: =AI10*G10 -> 10465112 | AK10: Резерв | AL10: 0.1 | AM10: =PriceList[[#This Row],[ИТОГ Цена за кв.м, руб]]*(1+PriceList[[#This Row],[Максимальная скидка]]) -> 402504.3 | AN10: =PriceList[[#This Row],[Цена за кв.м. в CRM]]*PriceList[[#This Row],[Площадь, кв.м]] -> 11511623 | AO10: 6000 | AP10: =PriceList[[#This Row],[Цена за кв.м. в CRM]]+PriceList[[#This Row],[Бронь]] -> 408504.3 | AQ10: =PriceList[[#This Row],[Цена за кв.м. в сайт]]*PriceList[[#This Row],[Площадь, кв.м]] -> 11683223 | AR10: =B10 -> С1-105 | AS10: =H10 -> Ст | AT10: =G10 -> 28.6 | AU10: =PriceList[[#This Row],[Цена за кв.м. в CRM]] -> 402504.3 | AV10: =AK10 -> Резерв | AZ10: =(PriceList[[#This Row],[Цена за кв.м. в сайт]])+$AZ$1 -> 409004.3 | BA10: =AZ10*PriceList[[#This Row],[Площадь, кв.м]] -> 11697523 | BB10: =BA10-PriceList[[#This Row],[Стоимость, руб для сбронированием]] -> 14300 | BD10: =MROUND(AZ10,100) -> 409000 | BE10: =BD10*PriceList[[#This Row],[Площадь, кв.м]] -> 11697400 | BG10: =BE10-$BG$1*PriceList[[#This Row],[Площадь, кв.м]] -> 11525800 | BH10: =BE10-BG10 -> 171600 | BI10: =BG10/PriceList[[#This Row],[Площадь, кв.м]] -> 403000 | BJ10: =BH10/BG10 -> 0.014888337
A11: 106 | B11: С1-106 | C11: 106 | D11: С1 | E11: 4 | F11: 11 | G11: 29.24 | H11: Ст | I11: Ст | J11: 4.25 | K11: =ROUND(J11*0.3,2) -> 1.28 | L11: =G11-J11 -> 24.99 | M11: =L11+K11 -> 26.27 | N11: S | O11: Линейная | P11: Правильная | Q11: Зона 3 | R11: Море | S11: Море | T11: Стандарт | U11: 42 | V11: =IFERROR(VLOOKUP(H11,'Коэфф для прайса 1 оч'!$A$3:$C$6,3,0),"") -> 327000 | W11: =IFERROR(VLOOKUP(E11,'Коэфф для прайса 1 оч'!$A$10:$C$23,3,0),"") -> 0 | X11: =IFERROR(VLOOKUP(N11,'Коэфф для прайса 1 оч'!$E$25:$F$30,2,0),"") -> 0.04 | Y11: =IFERROR(VLOOKUP(O11,'Коэфф для прайса 1 оч'!$E$32:$F$34,2,0),"") -> 0 | Z11: =IFERROR(VLOOKUP(P11,'Коэфф для прайса 1 оч'!$E$36:$F$38,2,0),"") -> 0.03 | AA11: =IFERROR(VLOOKUP(Q11,'Коэфф для прайса 1 оч'!$E$40:$F$43,2,0),"") -> -0.005 | AB11: =IFERROR(VLOOKUP(R11,'Коэфф для прайса 1 оч'!$E$45:$F$59,2,0),"") -> 0.07 | AC11: =IFERROR(VLOOKUP(T11,'Коэфф для прайса 1 оч'!$E$61:$F$67,2,0),"") -> 0 | AD11: =IFERROR(VLOOKUP(U11,'Коэфф для прайса 1 оч'!$E$69:$F$82,2,0),"") -> -0.016 | AE11: =IFERROR(VLOOKUP(PriceList[[#This Row],[Корпус]],'Коэфф для прайса 1 оч'!$I$10:$J$15,2,0),"") -> 0 | AF11: =ROUND(V11+(V11*SUM(W11:AE11)),2) -> 365913 | AG11: =AF11*G11 -> 10699296 | AH11: 0 | AI11: =AF11+AF11*AH11 -> 365913 | AJ11: =AI11*G11 -> 10699296 | AK11: Резерв | AL11: 0.1 | AM11: =PriceList[[#This Row],[ИТОГ Цена за кв.м, руб]]*(1+PriceList[[#This Row],[Максимальная скидка]]) -> 402504.3 | AN11: =PriceList[[#This Row],[Цена за кв.м. в CRM]]*PriceList[[#This Row],[Площадь, кв.м]] -> 11769226 | AO11: 6000 | AP11: =PriceList[[#This Row],[Цена за кв.м. в CRM]]+PriceList[[#This Row],[Бронь]] -> 408504.3 | AQ11: =PriceList[[#This Row],[Цена за кв.м. в сайт]]*PriceList[[#This Row],[Площадь, кв.м]] -> 11944666 | AR11: =B11 -> С1-106 | AS11: =H11 -> Ст | AT11: =G11 -> 29.24 | AU11: =PriceList[[#This Row],[Цена за кв.м. в CRM]] -> 402504.3 | AV11: =AK11 -> Резерв | AZ11: =(PriceList[[#This Row],[Цена за кв.м. в сайт]])+$AZ$1 -> 409004.3 | BA11: =AZ11*PriceList[[#This Row],[Площадь, кв.м]] -> 11959286 | BB11: =BA11-PriceList[[#This Row],[Стоимость, руб для сбронированием]] -> 14620 | BD11: =MROUND(AZ11,100) -> 409000 | BE11: =BD11*PriceList[[#This Row],[Площадь, кв.м]] -> 11959160 | BG11: =BE11-$BG$1*PriceList[[#This Row],[Площадь, кв.м]] -> 11783720 | BH11: =BE11-BG11 -> 175440 | BI11: =BG11/PriceList[[#This Row],[Площадь, кв.м]] -> 403000 | BJ11: =BH11/BG11 -> 0.014888337
A12: 107 | B12: С1-107 | C12: 107 | D12: С1 | E12: 4 | F12: 12 | G12: 29.24 | H12: Ст | I12: Ст | J12: 4.25 | K12: =ROUND(J12*0.3,2) -> 1.28 | L12: =G12-J12 -> 24.99 | M12: =L12+K12 -> 26.27 | N12: S | O12: Линейная | P12: Правильная | Q12: Зона 3 | R12: Море | S12: Море | T12: Стандарт | U12: 42 | V12: =IFERROR(VLOOKUP(H12,'Коэфф для прайса 1 оч'!$A$3:$C$6,3,0),"") -> 327000 | W12: =IFERROR(VLOOKUP(E12,'Коэфф для прайса 1 оч'!$A$10:$C$23,3,0),"") -> 0 | X12: =IFERROR(VLOOKUP(N12,'Коэфф для прайса 1 оч'!$E$25:$F$30,2,0),"") -> 0.04 | Y12: =IFERROR(VLOOKUP(O12,'Коэфф для прайса 1 оч'!$E$32:$F$34,2,0),"") -> 0 | Z12: =IFERROR(VLOOKUP(P12,'Коэфф для прайса 1 оч'!$E$36:$F$38,2,0),"") -> 0.03 | AA12: =IFERROR(VLOOKUP(Q12,'Коэфф для прайса 1 оч'!$E$40:$F$43,2,0),"") -> -0.005 | AB12: =IFERROR(VLOOKUP(R12,'Коэфф для прайса 1 оч'!$E$45:$F$59,2,0),"") -> 0.07 | AC12: =IFERROR(VLOOKUP(T12,'Коэфф для прайса 1 оч'!$E$61:$F$67,2,0),"") -> 0 | AD12: =IFERROR(VLOOKUP(U12,'Коэфф для прайса 1 оч'!$E$69:$F$82,2,0),"") -> -0.016 | AE12: =IFERROR(VLOOKUP(PriceList[[#This Row],[Корпус]],'Коэфф для прайса 1 оч'!$I$10:$J$15,2,0),"") -> 0 | AF12: =ROUND(V12+(V12*SUM(W12:AE12)),2) -> 365913 | AG12: =AF12*G12 -> 10699296 | AH12: 0 | AI12: =AF12+AF12*AH12 -> 365913 | AJ12: =AI12*G12 -> 10699296 | AK12: Резерв | AL12: 0.1 | AM12: =PriceList[[#This Row],[ИТОГ Цена за кв.м, руб]]*(1+PriceList[[#This Row],[Максимальная скидка]]) -> 402504.3 | AN12: =PriceList[[#This Row],[Цена за кв.м. в CRM]]*PriceList[[#This Row],[Площадь, кв.м]] -> 11769226 | AO12: 6000 | AP12: =PriceList[[#This Row],[Цена за кв.м. в CRM]]+PriceList[[#This Row],[Бронь]] -> 408504.3 | AQ12: =PriceList[[#This Row],[Цена за кв.м. в сайт]]*PriceList[[#This Row],[Площадь, кв.м]] -> 11944666 | AR12: =B12 -> С1-107 | AS12: =H12 -> Ст | AT12: =G12 -> 29.24 | AU12: =PriceList[[#This Row],[Цена за кв.м. в CRM]] -> 402504.3 | AV12: =AK12 -> Резерв | AZ12: =(PriceList[[#This Row],[Цена за кв.м. в сайт]])+$AZ$1 -> 409004.3 | BA12: =AZ12*PriceList[[#This Row],[Площадь, кв.м]] -> 11959286 | BB12: =BA12-PriceList[[#This Row],[Стоимость, руб для сбронированием]] -> 14620 | BD12: =MROUND(AZ12,100) -> 409000 | BE12: =BD12*PriceList[[#This Row],[Площадь, кв.м]] -> 11959160 | BG12: =BE12-$BG$1*PriceList[[#This Row],[Площадь, кв.м]] -> 11783720 | BH12: =BE12-BG12 -> 175440 | BI12: =BG12/PriceList[[#This Row],[Площадь, кв.м]] -> 403000 | BJ12: =BH12/BG12 -> 0.014888337
A13: 108 | B13: С1-108 | C13: 108 | D13: С1 | E13: 4 | F13: 13 | G13: 29.24 | H13: Ст | I13: Ст | J13: 4.25 | K13: =ROUND(J13*0.3,2) -> 1.28 | L13: =G13-J13 -> 24.99 | M13: =L13+K13 -> 26.27 | N13: S | O13: Линейная | P13: Правильная | Q13: Зона 2 | R13: Море | S13: Море | T13: Стандарт | U13: 42 | V13: =IFERROR(VLOOKUP(H13,'Коэфф для прайса 1 оч'!$A$3:$C$6,3,0),"") -> 327000 | W13: =IFERROR(VLOOKUP(E13,'Коэфф для прайса 1 оч'!$A$10:$C$23,3,0),"") -> 0 | X13: =IFERROR(VLOOKUP(N13,'Коэфф для прайса 1 оч'!$E$25:$F$30,2,0),"") -> 0.04 | Y13: =IFERROR(VLOOKUP(O13,'Коэфф для прайса 1 оч'!$E$32:$F$34,2,0),"") -> 0 | Z13: =IFERROR(VLOOKUP(P13,'Коэфф для прайса 1 оч'!$E$36:$F$38,2,0),"") -> 0.03 | AA13: =IFERROR(VLOOKUP(Q13,'Коэфф для прайса 1 оч'!$E$40:$F$43,2,0),"") -> 0 | AB13: =IFERROR(VLOOKUP(R13,'Коэфф для прайса 1 оч'!$E$45:$F$59,2,0),"") -> 0.07 | AC13: =IFERROR(VLOOKUP(T13,'Коэфф для прайса 1 оч'!$E$61:$F$67,2,0),"") -> 0 | AD13: =IFERROR(VLOOKUP(U13,'Коэфф для прайса 1 оч'!$E$69:$F$82,2,0),"") -> -0.016 | AE13: =IFERROR(VLOOKUP(PriceList[[#This Row],[Корпус]],'Коэфф для прайса 1 оч'!$I$10:$J$15,2,0),"") -> 0 | AF13: =ROUND(V13+(V13*SUM(W13:AE13)),2) -> 367548 | AG13: =AF13*G13 -> 10747104 | AH13: 0 | AI13: =AF13+AF13*AH13 -> 367548 | AJ13: =AI13*G13 -> 10747104 | AK13: Резерв | AL13: 0.1 | AM13: =PriceList[[#This Row],[ИТОГ Цена за кв.м, руб]]*(1+PriceList[[#This Row],[Максимальная скидка]]) -> 404302.8 | AN13: =PriceList[[#This Row],[Цена за кв.м. в CRM]]*PriceList[[#This Row],[Площадь, кв.м]] -> 11821814 | AO13: 6000 | AP13: =PriceList[[#This Row],[Цена за кв.м. в CRM]]+PriceList[[#This Row],[Бронь]] -> 410302.8 | AQ13: =PriceList[[#This Row],[Цена за кв.м. в сайт]]*PriceList[[#This Row],[Площадь, кв.м]] -> 11997254 | AR13: =B13 -> С1-108 | AS13: =H13 -> Ст | AT13: =G13 -> 29.24 | AU13: =PriceList[[#This Row],[Цена за кв.м. в CRM]] -> 404302.8 | AV13: =AK13 -> Резерв | AZ13: =(PriceList[[#This Row],[Цена за кв.м. в сайт]])+$AZ$1 -> 410802.8 | BA13: =AZ13*PriceList[[#This Row],[Площадь, кв.м]] -> 12011874 | BB13: =BA13-PriceList[[#This Row],[Стоимость, руб для сбронированием]] -> 14620 | BD13: =MROUND(AZ13,100) -> 410800 | BE13: =BD13*PriceList[[#This Row],[Площадь, кв.м]] -> 12011792 | BG13: =BE13-$BG$1*PriceList[[#This Row],[Площадь, кв.м]] -> 11836352 | BH13: =BE13-BG13 -> 175440 | BI13: =BG13/PriceList[[#This Row],[Площадь, кв.м]] -> 404800 | BJ13: =BH13/BG13 -> 0.014822134
A14: 109 | B14: С1-109 | C14: 109 | D14: С1 | E14: 4 | F14: 14 | G14: 29.24 | H14: Ст | I14: Ст | J14: 4.25 | K14: =ROUND(J14*0.3,2) -> 1.28 | L14: =G14-J14 -> 24.99 | M14: =L14+K14 -> 26.27 | N14: S | O14: Линейная | P14: Правильная | Q14: Зона 2 | R14: Море | S14: Море | T14: Стандарт | U14: 42 | V14: =IFERROR(VLOOKUP(H14,'Коэфф для прайса 1 оч'!$A$3:$C$6,3,0),"") -> 327000 | W14: =IFERROR(VLOOKUP(E14,'Коэфф для прайса 1 оч'!$A$10:$C$23,3,0),"") -> 0 | X14: =IFERROR(VLOOKUP(N14,'Коэфф для прайса 1 оч'!$E$25:$F$30,2,0),"") -> 0.04 | Y14: =IFERROR(VLOOKUP(O14,'Коэфф для прайса 1 оч'!$E$32:$F$34,2,0),"") -> 0 | Z14: =IFERROR(VLOOKUP(P14,'Коэфф для прайса 1 оч'!$E$36:$F$38,2,0),"") -> 0.03 | AA14: =IFERROR(VLOOKUP(Q14,'Коэфф для прайса 1 оч'!$E$40:$F$43,2,0),"") -> 0 | AB14: =IFERROR(VLOOKUP(R14,'Коэфф для прайса 1 оч'!$E$45:$F$59,2,0),"") -> 0.07 | AC14: =IFERROR(VLOOKUP(T14,'Коэфф для прайса 1 оч'!$E$61:$F$67,2,0),"") -> 0 | AD14: =IFERROR(VLOOKUP(U14,'Коэфф для прайса 1 оч'!$E$69:$F$82,2,0),"") -> -0.016 | AE14: =IFERROR(VLOOKUP(PriceList[[#This Row],[Корпус]],'Коэфф для прайса 1 оч'!$I$10:$J$15,2,0),"") -> 0 | AF14: =ROUND(V14+(V14*SUM(W14:AE14)),2) -> 367548 | AG14: =AF14*G14 -> 10747104 | AH14: 0 | AI14: =AF14+AF14*AH14 -> 367548 | AJ14: =AI14*G14 -> 10747104 | AK14: Резерв | AL14: 0.1 | AM14: =PriceList[[#This Row],[ИТОГ Цена за кв.м, руб]]*(1+PriceList[[#This Row],[Максимальная скидка]]) -> 404302.8 | AN14: =PriceList[[#This Row],[Цена за кв.м. в CRM]]*PriceList[[#This Row],[Площадь, кв.м]] -> 11821814 | AO14: 6000 | AP14: =PriceList[[#This Row],[Цена за кв.м. в CRM]]+PriceList[[#This Row],[Бронь]] -> 410302.8 | AQ14: =PriceList[[#This Row],[Цена за кв.м. в сайт]]*PriceList[[#This Row],[Площадь, кв.м]] -> 11997254 | AR14: =B14 -> С1-109 | AS14: =H14 -> Ст | AT14: =G14 -> 29.24 | AU14: =PriceList[[#This Row],[Цена за кв.м. в CRM]] -> 404302.8 | AV14: =AK14 -> Резерв | AZ14: =(PriceList[[#This Row],[Цена за кв.м. в сайт]])+$AZ$1 -> 410802.8 | BA14: =AZ14*PriceList[[#This Row],[Площадь, кв.м]] -> 12011874 | BB14: =BA14-PriceList[[#This Row],[Стоимость, руб для сбронированием]] -> 14620 | BD14: =MROUND(AZ14,100) -> 410800 | BE14: =BD14*PriceList[[#This Row],[Площадь, кв.м]] -> 12011792 | BG14: =BE14-$BG$1*PriceList[[#This Row],[Площадь, кв.м]] -> 11836352 | BH14: =BE14-BG14 -> 175440 | BI14: =BG14/PriceList[[#This Row],[Площадь, кв.м]] -> 404800 | BJ14: =BH14/BG14 -> 0.014822134
A15: 11 | B15: С1-11 | C15: 11 | D15: С1 | E15: 1 | F15: 11 | G15: 49.81 | H15: Ст | I15: Ст | J15: 10.87 | K15: =ROUND(J15*0.3,2) -> 3.26 | L15: =G15-J15 -> 38.94 | M15: =L15+K15 -> 42.2 | N15: XL | O15: Линейная | P15: Правильная | Q15: Зона 1 | R15: Двор северо-восток | S15: Двор | T15: Около/над входной группой | U15: 13 | V15: =IFERROR(VLOOKUP(H15,'Коэфф для прайса 1 оч'!$A$3:$C$6,3,0),"") -> 327000 | W15: =IFERROR(VLOOKUP(E15,'Коэфф для прайса 1 оч'!$A$10:$C$23,3,0),"") -> -0.045 | X15: =IFERROR(VLOOKUP(N15,'Коэфф для прайса 1 оч'!$E$25:$F$30,2,0),"") -> -0.02 | Y15: =IFERROR(VLOOKUP(O15,'Коэфф для прайса 1 оч'!$E$32:$F$34,2,0),"") -> 0 | Z15: =IFERROR(VLOOKUP(P15,'Коэфф для прайса 1 оч'!$E$36:$F$38,2,0),"") -> 0.03 | AA15: =IFERROR(VLOOKUP(Q15,'Коэфф для прайса 1 оч'!$E$40:$F$43,2,0),"") -> 0.005 | AB15: =IFERROR(VLOOKUP(R15,'Коэфф для прайса 1 оч'!$E$45:$F$59,2,0),"") -> -0.01 | AC15: =IFERROR(VLOOKUP(T15,'Коэфф для прайса 1 оч'!$E$61:$F$67,2,0),"") -> -0.01 | AD15: =IFERROR(VLOOKUP(U15,'Коэфф для прайса 1 оч'!$E$69:$F$82,2,0),"") -> 0.013 | AE15: =IFERROR(VLOOKUP(PriceList[[#This Row],[Корпус]],'Коэфф для прайса 1 оч'!$I$10:$J$15,2,0),"") -> 0 | AF15: =ROUND(V15+(V15*SUM(W15:AE15)),2) -> 314901 | AG15: =AF15*G15 -> 15685219 | AH15: 0 | AI15: =AF15+AF15*AH15 -> 314901 | AJ15: =AI15*G15 -> 15685219 | AK15: Резерв | AL15: 0.1 | AM15: =PriceList[[#This Row],[ИТОГ Цена за кв.м, руб]]*(1+PriceList[[#This Row],[Максимальная скидка]]) -> 346391.1 | AN15: =PriceList[[#This Row],[Цена за кв.м. в CRM]]*PriceList[[#This Row],[Площадь, кв.м]] -> 17253741 | AO15: 6000 | AP15: =PriceList[[#This Row],[Цена за кв.м. в CRM]]+PriceList[[#This Row],[Бронь]] -> 352391.1 | AQ15: =PriceList[[#This Row],[Цена за кв.м. в сайт]]*PriceList[[#This Row],[Площадь, кв.м]] -> 17552601 | AR15: =B15 -> С1-11 | AS15: =H15 -> Ст | AT15: =G15 -> 49.81 | AU15: =PriceList[[#This Row],[Цена за кв.м. в CRM]] -> 346391.1 | AV15: =AK15 -> Резерв | AZ15: =(PriceList[[#This Row],[Цена за кв.м. в сайт]])+$AZ$1 -> 352891.1 | BA15: =AZ15*PriceList[[#This Row],[Площадь, кв.м]] -> 17577506 | BB15: =BA15-PriceList[[#This Row],[Стоимость, руб для сбронированием]] -> 24905 | BD15: =MROUND(AZ15,100) -> 352900 | BE15: =BD15*PriceList[[#This Row],[Площадь, кв.м]] -> 17577949 | BG15: =BE15-$BG$1*PriceList[[#This Row],[Площадь, кв.м]] -> 17279089 | BH15: =BE15-BG15 -> 298860 | BI15: =BG15/PriceList[[#This Row],[Площадь, кв.м]] -> 346900 | BJ15: =BH15/BG15 -> 0.017296051
A16: 110 | B16: С1-110 | C16: 110 | D16: С1 | E16: 4 | F16: 15 | G16: 53.23 | H16: 1К | I16: 1АЕ | J16: 4.76 | K16: =ROUND(J16*0.3,2) -> 1.43 | L16: =G16-J16 -> 48.47 | M16: =L16+K16 -> 49.9 | N16: L | O16: Линейная | P16: Правильная | Q16: Зона 2 | R16: Море | S16: Море | T16: Стандарт | U16: 42 | V16: =IFERROR(VLOOKUP(H16,'Коэфф для прайса 1 оч'!$A$3:$C$6,3,0),"") -> 313920 | W16: =IFERROR(VLOOKUP(E16,'Коэфф для прайса 1 оч'!$A$10:$C$23,3,0),"") -> 0 | X16: =IFERROR(VLOOKUP(N16,'Коэфф для прайса 1 оч'!$E$25:$F$30,2,0),"") -> -0.01 | Y16: =IFERROR(VLOOKUP(O16,'Коэфф для прайса 1 оч'!$E$32:$F$34,2,0),"") -> 0 | Z16: =IFERROR(VLOOKUP(P16,'Коэфф для прайса 1 оч'!$E$36:$F$38,2,0),"") -> 0.03 | AA16: =IFERROR(VLOOKUP(Q16,'Коэфф для прайса 1 оч'!$E$40:$F$43,2,0),"") -> 0 | AB16: =IFERROR(VLOOKUP(R16,'Коэфф для прайса 1 оч'!$E$45:$F$59,2,0),"") -> 0.07 | AC16: =IFERROR(VLOOKUP(T16,'Коэфф для прайса 1 оч'!$E$61:$F$67,2,0),"") -> 0 | AD16: =IFERROR(VLOOKUP(U16,'Коэфф для прайса 1 оч'!$E$69:$F$82,2,0),"") -> -0.016 | AE16: =IFERROR(VLOOKUP(PriceList[[#This Row],[Корпус]],'Коэфф для прайса 1 оч'!$I$10:$J$15,2,0),"") -> 0 | AF16: =ROUND(V16+(V16*SUM(W16:AE16)),2) -> 337150.08 | AG16: =AF16*G16 -> 17946499 | AH16: 0 | AI16: =AF16+AF16*AH16 -> 337150.08 | AJ16: =AI16*G16 -> 17946499 | AK16: Резерв | AL16: 0.1 | AM16: =PriceList[[#This Row],[ИТОГ Цена за кв.м, руб]]*(1+PriceList[[#This Row],[Максимальная скидка]]) -> 370865.09 | AN16: =PriceList[[#This Row],[Цена за кв.м. в CRM]]*PriceList[[#This Row],[Площадь, кв.м]] -> 19741149 | AO16: 6000 | AP16: =PriceList[[#This Row],[Цена за кв.м. в CRM]]+PriceList[[#This Row],[Бронь]] -> 376865.09 | AQ16: =PriceList[[#This Row],[Цена за кв.м. в сайт]]*PriceList[[#This Row],[Площадь, кв.м]] -> 20060529 | AR16: =B16 -> С1-110 | AS16: =H16 -> 1К | AT16: =G16 -> 53.23 | AU16: =PriceList[[#This Row],[Цена за кв.м. в CRM]] -> 370865.09 | AV16: =AK16 -> Резерв | AZ16: =(PriceList[[#This Row],[Цена за кв.м. в сайт]])+$AZ$1 -> 377365.09 | BA16: =AZ16*PriceList[[#This Row],[Площадь, кв.м]] -> 20087144 | BB16: =BA16-PriceList[[#This Row],[Стоимость, руб для сбронированием]] -> 26615 | BD16: =MROUND(AZ16,100) -> 377400 | BE16: =BD16*PriceList[[#This Row],[Площадь, кв.м]] -> 20089002 | BG16: =BE16-$BG$1*PriceList[[#This Row],[Площадь, кв.м]] -> 19769622 | BH16: =BE16-BG16 -> 319380 | BI16: =BG16/PriceList[[#This Row],[Площадь, кв.м]] -> 371400 | BJ16: =BH16/BG16 -> 0.016155089
A17: 111 | B17: С1-111 | C17: 111 | D17: С1 | E17: 4 | F17: 16 | G17: 30.71 | H17: Ст | I17: Ст | J17: 5.97 | K17: =ROUND(J17*0.3,2) -> 1.79 | L17: =G17-J17 -> 24.74 | M17: =L17+K17 -> 26.53 | N17: S | O17: Линейная | P17: Правильная | Q17: Зона 1 | R17: Море | S17: Море | T17: Стандарт | U17: 42 | V17: =IFERROR(VLOOKUP(H17,'Коэфф для прайса 1 оч'!$A$3:$C$6,3,0),"") -> 327000 | W17: =IFERROR(VLOOKUP(E17,'Коэфф для прайса 1 оч'!$A$10:$C$23,3,0),"") -> 0 | X17: =IFERROR(VLOOKUP(N17,'Коэфф для прайса 1 оч'!$E$25:$F$30,2,0),"") -> 0.04 | Y17: =IFERROR(VLOOKUP(O17,'Коэфф для прайса 1 оч'!$E$32:$F$34,2,0),"") -> 0 | Z17: =IFERROR(VLOOKUP(P17,'Коэфф для прайса 1 оч'!$E$36:$F$38,2,0),"") -> 0.03 | AA17: =IFERROR(VLOOKUP(Q17,'Коэфф для прайса 1 оч'!$E$40:$F$43,2,0),"") -> 0.005 | AB17: =IFERROR(VLOOKUP(R17,'Коэфф для прайса 1 оч'!$E$45:$F$59,2,0),"") -> 0.07 | AC17: =IFERROR(VLOOKUP(T17,'Коэфф для прайса 1 оч'!$E$61:$F$67,2,0),"") -> 0 | AD17: =IFERROR(VLOOKUP(U17,'Коэфф для прайса 1 оч'!$E$69:$F$82,2,0),"") -> -0.016 | AE17: =IFERROR(VLOOKUP(PriceList[[#This Row],[Корпус]],'Коэфф для прайса 1 оч'!$I$10:$J$15,2,0),"") -> 0 | AF17: =ROUND(V17+(V17*SUM(W17:AE17)),2) -> 369183 | AG17: =AF17*G17 -> 11337610 | AH17: 0 | AI17: =AF17+AF17*AH17 -> 369183 | AJ17: =AI17*G17 -> 11337610 | AK17: Резерв | AL17: 0.1 | AM17: =PriceList[[#This Row],[ИТОГ Цена за кв.м, руб]]*(1+PriceList[[#This Row],[Максимальная скидка]]) -> 406101.3 | AN17: =PriceList[[#This Row],[Цена за кв.м. в CRM]]*PriceList[[#This Row],[Площадь, кв.м]] -> 12471371 | AO17: 6000 | AP17: =PriceList[[#This Row],[Цена за кв.м. в CRM]]+PriceList[[#This Row],[Бронь]] -> 412101.3 | AQ17: =PriceList[[#This Row],[Цена за кв.м. в сайт]]*PriceList[[#This Row],[Площадь, кв.м]] -> 12655631 | AR17: =B17 -> С1-111 | AS17: =H17 -> Ст | AT17: =G17 -> 30.71 | AU17: =PriceList[[#This Row],[Цена за кв.м. в CRM]] -> 406101.3 | AV17: =AK17 -> Резерв | AZ17: =(PriceList[[#This Row],[Цена за кв.м. в сайт]])+$AZ$1 -> 412601.3 | BA17: =AZ17*PriceList[[#This Row],[Площадь, кв.м]] -> 12670986 | BB17: =BA17-PriceList[[#This Row],[Стоимость, руб для сбронированием]] -> 15355 | BD17: =MROUND(AZ17,100) -> 412600 | BE17: =BD17*PriceList[[#This Row],[Площадь, кв.м]] -> 12670946 | BG17: =BE17-$BG$1*PriceList[[#This Row],[Площадь, кв.м]] -> 12486686 | BH17: =BE17-BG17 -> 184260 | BI17: =BG17/PriceList[[#This Row],[Площадь, кв.м]] -> 406600 | BJ17: =BH17/BG17 -> 0.014756517
